Workbook

Sheet Master
A1: Year | B1: 2026
B3: =DATE($B$1,1,COLUMN()-1) -> 46023 | C3: =DATE($B$1,1,COLUMN()-1) -> 46024 | D3: =DATE($B$1,1,COLUMN()-1) -> 46025 | E3: =DATE($B$1,1,COLUMN()-1) -> 46026 | F3: =DATE($B$1,1,COLUMN()-1) -> 46027 | G3: =DATE($B$1,1,COLUMN()-1) -> 46028 | H3: =DATE($B$1,1,COLUMN()-1) -> 46029 | I3: =DATE($B$1,1,COLUMN()-1) -> 46030 | ... AF3: =DATE($B$1,1,COLUMN()-1) -> 46053 | AH3: Red date=PH
B4: =TEXT(B3,"ddd") -> Thu | C4: =TEXT(C3,"ddd") -> Fri | D4: =TEXT(D3,"ddd") -> Sat | E4: =TEXT(E3,"ddd") -> Sun | F4: =TEXT(F3,"ddd") -> Mon | G4: =TEXT(G3,"ddd") -> Tue | H4: =TEXT(H3,"ddd") -> Wed | I4: =TEXT(I3,"ddd") -> Thu | ... AF4: =TEXT(AF3,"ddd") -> Sat | AH4: Highlight = Sun
B5: A Lam | C5: A Lam | D5: A Lam | E5: A Lam | F5: Dicky | G5: Dicky | H5: Dicky | I5: Dicky | J5: Dicky | K5: Dicky | L5: Dicky | M5: Amy | N5: Amy | O5: Amy | P5: Ka Po | Q5: Amy | R5: Amy | S5: Amy | T5: Amy | U5: Amy | V5: Amy | W5: Amy | X5: Amy | Y5: Amy | Z5: Amy | AA5: Dicky | AB5: Dicky | AC5: Dicky | AD5: Dicky | AE5: Dicky | AF5: Dicky | AH5: Red date = PH on Sat
B6: Melody | C6: Melody | D6: Melody | E6: Melody | F6: Melody | G6: Melody | H6: Melody | I6: Melody | J6: Melody | K6: Melody | L6: Melody | M6: A Lam | N6: A Lam | O6: A Lam | P6: A Lam | Q6: A Lam | R6: Ka Po | S6: Ka Po | T6: A Lam | U6: A Lam | V6: A Lam | W6: A Lam | X6: A Lam | Y6: A Lam | Z6: A Lam | AA6: Ka Po | AB6: Ka Po | AC6: Ka Po | AD6: Ka Po | AE6: Ka Po | AF6: Ka Po
B7: Katrina | C7: Katrina | D7: Katrina | E7: Katrina | F7: Ka Po | G7: Amy | H7: Ka Po | I7: Ka Po | J7: Ka Po | K7: A Lam | L7: A Lam | M7: Katrina | N7: Katrina | O7: Katrina | P7: Katrina | Q7: Katrina | R7: Katrina | S7: Katrina | T7: Melody | U7: Melody | V7: Melody | W7: Melody | X7: Melody | Y7: Ka Po | Z7: Ka Po | AA7: Melody | AB7: Melody | AC7: Melody | AD7: Melody | AE7: Melody | AF7: Katrina
T9: Dicky | U9: Dicky | V9: Dicky | W9: Dicky | X9: Dicky | Y9: Dicky | Z9: Dicky | AA9: A LAM | AB9: A LAM | AC9: A LAM | AD9: A LAM | AE9: A LAM | AF9: A LAM
B12: =DATE($B$1,2,COLUMN()-1) -> 46054 | C12: =DATE($B$1,2,COLUMN()-1) -> 46055 | D12: =DATE($B$1,2,COLUMN()-1) -> 46056 | E12: =DATE($B$1,2,COLUMN()-1) -> 46057 | F12: =DATE($B$1,2,COLUMN()-1) -> 46058 | G12: =DATE($B$1,2,COLUMN()-1) -> 46059 | H12: =DATE($B$1,2,COLUMN()-1) -> 46060 | I12: =DATE($B$1,2,COLUMN()-1) -> 46061 | ... AC12: =DATE($B$1,2,COLUMN()-1) -> 46081
B13: =TEXT(B12,"ddd") -> Sun | C13: =TEXT(C12,"ddd") -> Mon | D13: =TEXT(D12,"ddd") -> Tue | E13: =TEXT(E12,"ddd") -> Wed | F13: =TEXT(F12,"ddd") -> Thu | G13: =TEXT(G12,"ddd") -> Fri | H13: =TEXT(H12,"ddd") -> Sat | I13: =TEXT(I12,"ddd") -> Sun | ... AC13: =TEXT(AC12,"ddd") -> Sat
B14: Dicky | C14: Amy | D14: Amy | E14: Amy | F14: Amy | G14: Amy | H14: Amy | I14: Amy | J14: Dicky | K14: Dicky | L14: Dicky | M14: Dicky | N14: Dicky | O14: Dicky | P14: Dicky | Q14: Amy | R14: Amy | S14: Dicky | T14: Dicky | U14: Dicky | V14: Dicky | W14: Dicky | X14: Dicky | Y14: Dicky | Z14: Dicky | AA14: Dicky | AB14: Dicky | AC14: Melody
B15: Ka Po | C15: Ka Po | D15: Ka Po | E15: Ka Po | F15: Ka Po | G15: Ka Po | H15: Ka Po | I15: Ka Po | J15: A Lam | K15: A Lam | L15: A Lam | M15: A Lam | N15: A Lam | O15: A Lam | P15: A Lam | Q15: Katrina | R15: Katrina | S15: Katrina | T15: Katrina | U15: Katrina | V15: Katrina | W15: Katrina | X15: Katrina | Y15: Katrina | Z15: Katrina | AA15: Katrina | AB15: Katrina | AC15: Katrina
B16: Katrina | C16: Katrina | D16: Katrina | E16: Katrina | F16: Katrina | G16: Katrina | H16: Melody | I16: Melody | J16: Melody | K16: Melody | L16: Melody | M16: Melody | N16: Melody | O16: Melody | P16: Melody | Q16: Ka Po | R16: Ka Po | S16: Ka Po | T16: Ka Po | U16: Ka Po | V16: Ka Po | W16: Ka Po | X16: A Lam | Y16: A Lam | Z16: A Lam | AA16: A Lam | AB16: A Lam | AC16: A Lam
B18: A Lam | C18: A Lam | D18: A Lam | E18: A Lam | F18: A Lam | G18: A Lam | H18: A Lam | I18: A Lam | J18: KATRINA | K18: KATRINA | L18: KATRINA | M18: KATRINA | N18: KATRINA | O18: KATRINA | P18: KATRINA | Q18: Melody | R18: Melody | S18: Melody | T18: Melody | U18: Melody | V18: Melody | W18: Melody | X18: Melody | Y18: Melody | Z18: Melody | AA18: Melody | AB18: Melody | AC18: Melody
B21: =DATE($B$1,3,COLUMN()-1) -> 46082 | C21: =DATE($B$1,3,COLUMN()-1) -> 46083 | D21: =DATE($B$1,3,COLUMN()-1) -> 46084 | E21: =DATE($B$1,3,COLUMN()-1) -> 46085 | F21: =DATE($B$1,3,COLUMN()-1) -> 46086 | G21: =DATE($B$1,3,COLUMN()-1) -> 46087 | H21: =DATE($B$1,3,COLUMN()-1) -> 46088 | I21: =DATE($B$1,3,COLUMN()-1) -> 46089 | ... AF21: =DATE($B$1,3,COLUMN()-1) -> 46112
B22: =TEXT(B21,"ddd") -> Sun | C22: =TEXT(C21,"ddd") -> Mon | D22: =TEXT(D21,"ddd") -> Tue | E22: =TEXT(E21,"ddd") -> Wed | F22: =TEXT(F21,"ddd") -> Thu | G22: =TEXT(G21,"ddd") -> Fri | H22: =TEXT(H21,"ddd") -> Sat | I22: =TEXT(I21,"ddd") -> Sun | ... AF22: =TEXT(AF21,"ddd") -> Tue
B23: Melody | C23: Dicky | D23: Dicky | E23: Amy | F23: Amy | G23: Amy | H23: Amy | I23: Amy | J23: Amy | K23: Amy | L23: Amy | M23: Dicky | N23: Dicky | O23: Dicky | P23: Dicky | Q23: Amy | R23: Amy | S23: Amy | T23: Dicky | U23: Amy | V23: Amy | W23: Amy | X23: Amy | Y23: Amy | Z23: Amy | AA23: Amy | AB23: Amy | AC23: Amy | AD23: Amy | AE23: Dicky | AF23: Dicky
B24: Katrina | C24: Melody | D24: Melody | E24: Melody | F24: Melody | G24: Melody | H24: Melody | I24: Melody | J24: A Lam | K24: A Lam | L24: A Lam | M24: A Lam | N24: A Lam | O24: A Lam | P24: A Lam | Q24: Melody | R24: Melody | S24: Melody | T24: Melody | U24: Melody | V24: Melody | W24: Melody | X24: Katrina | Y24: Katrina | Z24: Katrina | AA24: Katrina | AB24: Katrina | AC24: Katrina | AD24: Katrina | AE24: A Lam | AF24: A Lam
B25: A Lam | C25: Ka Po | D25: Ka Po | E25: Ka Po | F25: Ka Po | G25: Ka Po | H25: Ka Po | I25: Ka Po | J25: Katrina | K25: Katrina | L25: Katrina | M25: Katrina | N25: Katrina | O25: Katrina | P25: Katrina | Q25: Ka Po | R25: Ka Po | S25: Ka Po | T25: Ka Po | U25: Ka Po | V25: Ka Po | W25: Ka Po | X25: Ka Po | Y25: Ka Po | Z25: Ka Po | AA25: Ka Po | AB25: Ka Po | AC25: Ka Po | AD25: Dicky | AE25: Dicky | AF25: Melody
X27: Ivy | Y27: IVY | Z27: IVY | AA27: IVY | AB27: IVY | AC27: IVY | AD27: IVY | AE27: IVY | AF27: IVY
B30: =DATE($B$1,4,COLUMN()-1) -> 46113 | C30: =DATE($B$1,4,COLUMN()-1) -> 46114 | D30: =DATE($B$1,4,COLUMN()-1) -> 46115 | E30: =DATE($B$1,4,COLUMN()-1) -> 46116 | F30: =DATE($B$1,4,COLUMN()-1) -> 46117 | G30: =DATE($B$1,4,COLUMN()-1) -> 46118 | H30: =DATE($B$1,4,COLUMN()-1) -> 46119 | I30: =DATE($B$1,4,COLUMN()-1) -> 46120 | ... AE30: =DATE($B$1,4,COLUMN()-1) -> 46142
B31: =TEXT(B30,"ddd") -> Wed | C31: =TEXT(C30,"ddd") -> Thu | D31: =TEXT(D30,"ddd") -> Fri | E31: =TEXT(E30,"ddd") -> Sat | F31: =TEXT(F30,"ddd") -> Sun | G31: =TEXT(G30,"ddd") -> Mon | H31: =TEXT(H30,"ddd") -> Tue | I31: =TEXT(I30,"ddd") -> Wed | ... AE31: =TEXT(AE30,"ddd") -> Thu
B32: Dicky | C32: Dicky | D32: Dicky | E32: Dicky | F32: Dicky | G32: Amy | H32: Amy | I32: Dicky | J32: Dicky | K32: Dicky | L32: Dicky | M32: Dicky | N32: Amy | O32: Amy | P32: Amy | Q32: Amy | R32: Amy | S32: Dicky | T32: Dicky | U32: Dicky | V32: Dicky | W32: Dicky | X32: Dicky | Y32: Dicky | Z32: Amy | AA32: Amy | AB32: Amy | AC32: Amy | AD32: Amy | AE32: Amy
B33: A Lam | C33: A Lam | D33: A Lam | E33: A Lam | F33: A Lam | G33: A Lam | H33: A Lam | I33: A Lam | J33: A Lam | K33: A Lam | L33: Katrina | M33: Katrina | N33: Ka Po | O33: Ka Po | P33: Ka Po | Q33: Ka Po | R33: Ka Po | S33: Ka Po | T33: Ka Po | U33: A Lam | V33: A Lam | W33: A Lam | X33: A Lam | Y33: A Lam | Z33: A Lam | AA33: A Lam | AB33: Ka Po | AC33: Ka Po | AD33: Ka Po | AE33: Ka Po
B34: Melody | C34: Melody | D34: Melody | E34: Melody | F34: Melody | G34: Melody | H34: Melody | I34: Amy | J34: Ka Po | K34: Amy | L34: Amy | M34: Amy | N34: Katrina | O34: Katrina | P34: Katrina | Q34: Katrina | R34: Katrina | S34: A Lam | T34: A Lam | U34: Melody | V34: Melody | W34: Melody | X34: Melody | Y34: Melody | Z34: Melody | AA34: Melody | AB34: Melody | AC34: Melody | AD34: Melody | AE34: Melody
B36: IVY | C36: IVY | D36: IVY | E36: IVY | F36: IVY | G36: YOKO | H36: YOKO | I36: YOKO | J36: YOKO | K36: YOKO | L36: YOKO
L37: Li Mui Ying | N37: Li Mui Ying
B39: =DATE($B$1,5,COLUMN()-1) -> 46143 | C39: =DATE($B$1,5,COLUMN()-1) -> 46144 | D39: =DATE($B$1,5,COLUMN()-1) -> 46145 | E39: =DATE($B$1,5,COLUMN()-1) -> 46146 | F39: =DATE($B$1,5,COLUMN()-1) -> 46147 | G39: =DATE($B$1,5,COLUMN()-1) -> 46148 | H39: =DATE($B$1,5,COLUMN()-1) -> 46149 | I39: =DATE($B$1,5,COLUMN()-1) -> 46150 | ... AF39: =DATE($B$1,5,COLUMN()-1) -> 46173 | AH39: Red date=PH
B40: =TEXT(B39,"ddd") -> Fri | C40: =TEXT(C39,"ddd") -> Sat | D40: =TEXT(D39,"ddd") -> Sun | E40: =TEXT(E39,"ddd") -> Mon | F40: =TEXT(F39,"ddd") -> Tue | G40: =TEXT(G39,"ddd") -> Wed | H40: =TEXT(H39,"ddd") -> Thu | I40: =TEXT(I39,"ddd") -> Fri | ... AF40: =TEXT(AF39,"ddd") -> Sun | AH40: Highlight = Sun
B41: Amy | C41: Amy | D41: Amy | E41: Dicky | F41: Dicky | G41: Dicky | H41: Dicky | I41: Amy | J41: Amy | K41: Amy | L41: Amy | M41: Amy | N41: Amy | O41: Amy | P41: Amy | Q41: Amy | R41: Amy | S41: Dicky | T41: Dicky | U41: Dicky | V41: Dicky | W41: Dicky | X41: Dicky | Y41: Dicky | Z41: Dicky | AA41: Dicky | AB41: Dicky | AC41: Dicky | AD41: Dicky | AE41: Dicky | AF41: Dicky | AH41: Red date = PH on Sat
B42: Ka Po | C42: Ka Po | D42: Ka Po | E42: A Lam | F42: A Lam | G42: A Lam | H42: A Lam | I42: A Lam | J42: A Lam | K42: A Lam | L42: Ka Po | M42: Ka Po | N42: Ka Po | O42: Ka Po | P42: Ka Po | Q42: Ka Po | R42: Ka Po | S42: A Lam | T42: A Lam | U42: A Lam | V42: A Lam | W42: Melody | X42: Melody | Y42: Melody | Z42: Melody | AA42: Melody | AB42: Ka Po | AC42: Ka Po | AD42: Ka Po | AE42: Ka Po | AF42: Ka Po
B43: A Lam | C43: A Lam | D43: A Lam | E43: Katrina | F43: Katrina | G43: Katrina | H43: Katrina | I43: Katrina | J43: Katrina | K43: Katrina | L43: Melody | M43: Melody | N43: Melody | O43: Melody | P43: Melody | Q43: Melody | R43: Melody | S43: Melody | T43: Katrina | U43: Katrina | V43: Katrina | W43: Katrina | X43: Katrina | Y43: Katrina | Z43: Katrina | AA43: Katrina | AB43: Katrina | AC43: Katrina | AD43: Katrina | AE43: Katrina | AF43: Katrina
W45: Amy | X45: Amy | Y45: Amy | Z45: Amy | AA45: Amy | AB45: Amy | AC45: Amy | AD45: Amy | AE45: Amy | AF45: Amy
B48: =DATE($B$1, 6, COLUMN()-1) -> 46174 | C48: =DATE($B$1, 6, COLUMN()-1) -> 46175 | D48: =DATE($B$1, 6, COLUMN()-1) -> 46176 | E48: =DATE($B$1, 6, COLUMN()-1) -> 46177 | F48: =DATE($B$1, 6, COLUMN()-1) -> 46178 | G48: =DATE($B$1, 6, COLUMN()-1) -> 46179 | H48: =DATE($B$1, 6, COLUMN()-1) -> 46180 | I48: =DATE($B$1, 6, COLUMN()-1) -> 46181 | ... AE48: =DATE($B$1, 6, COLUMN()-1) -> 46203
B49: =TEXT(B48,"ddd") -> Mon | C49: =TEXT(C48,"ddd") -> Tue | D49: =TEXT(D48,"ddd") -> Wed | E49: =TEXT(E48,"ddd") -> Thu | F49: =TEXT(F48,"ddd") -> Fri | G49: =TEXT(G48,"ddd") -> Sat | H49: =TEXT(H48,"ddd") -> Sun | I49: =TEXT(I48,"ddd") -> Mon | ... AE49: =TEXT(AE48,"ddd") -> Tue
B50: A Lam | C50: A Lam | D50: A Lam | E50: A Lam | F50: A Lam | G50: A Lam | H50: A Lam | I50: Amy | J50: Amy | K50: Amy | L50: Amy | M50: Amy | N50: Amy | O50: Amy | P50: Amy | Q50: Amy | R50: Amy | S50: Amy | T50: Amy | U50: Amy | V50: Amy | W50: Dicky | X50: Dicky | Y50: Dicky | Z50: Dicky | AA50: Dicky | AB50: Dicky | AC50: Dicky | AD50: Dicky | AE50: Dicky
B51: Melody | C51: Melody | D51: Melody | E51: Melody | F51: Melody | G51: Melody | H51: Melody | I51: A Lam | J51: A Lam | K51: A Lam | L51: A Lam | M51: A Lam | N51: A Lam | O51: A Lam | P51: Ka Po | Q51: Ka Po | R51: Ka Po | S51: Ka Po | T51: Ka Po | U51: Ka Po | V51: Ka Po | W51: A Lam | X51: A Lam | Y51: A Lam | Z51: A Lam | AA51: A Lam | AB51: A Lam | AC51: A Lam | AD51: Ka Po | AE51: Ka Po
B52: Ka Po | C52: Ka Po | D52: Ka Po | E52: Ka Po | F52: Ka Po | G52: Katrina | H52: Katrina | I52: Katrina | J52: Katrina | K52: Katrina | L52: Katrina | M52: Katrina | N52: Katrina | O52: Katrina | P52: Melody | Q52: Melody | R52: Melody | S52: Melody | T52: Melody | U52: Melody | V52: Melody | W52: Katrina | X52: Katrina | Y52: Katrina | Z52: Katrina | AA52: Katrina | AB52: Katrina | AC52: Katrina | AD52: A Lam | AE52: A Lam
B54: Amy | C54: Amy | D54: Amy | I54: Ka Po | J54: Ka Po | K54: Ka Po | L54: Ka Po | M54: Ka Po | N54: Ka Po | O54: Ka Po | W54: Ivy | X54: Ivy | Y54: Ivy | Z54: Ivy | AA54: Ivy | AB54: Ivy | AC54: Ivy | AD54: Ivy | AE54: Ivy
B57: =DATE($B$1, 7, COLUMN()-1) -> 46204 | C57: =DATE($B$1, 7, COLUMN()-1) -> 46205 | D57: =DATE($B$1, 7, COLUMN()-1) -> 46206 | E57: =DATE($B$1, 7, COLUMN()-1) -> 46207 | F57: =DATE($B$1, 7, COLUMN()-1) -> 46208 | G57: =DATE($B$1, 7, COLUMN()-1) -> 46209 | H57: =DATE($B$1, 7, COLUMN()-1) -> 46210 | I57: =DATE($B$1, 7, COLUMN()-1) -> 46211 | ... AF57: =DATE($B$1, 7, COLUMN()-1) -> 46234
B58: =TEXT(B57,"ddd") -> Wed | C58: =TEXT(C57,"ddd") -> Thu | D58: =TEXT(D57,"ddd") -> Fri | E58: =TEXT(E57,"ddd") -> Sat | F58: =TEXT(F57,"ddd") -> Sun | G58: =TEXT(G57,"ddd") -> Mon | H58: =TEXT(H57,"ddd") -> Tue | I58: =TEXT(I57,"ddd") -> Wed | ... AF58: =TEXT(AF57,"ddd") -> Fri
...

Sheet Jan
A1: Year | B1: =Master!B1 -> 2026
C3: =IFERROR(IF(Master!B3="", "", Master!B3), "") -> 46023 | D3: =IFERROR(IF(Master!C3="", "", Master!C3), "") -> 46024 | E3: =IFERROR(IF(Master!D3="", "", Master!D3), "") -> 46025 | F3: =IFERROR(IF(Master!E3="", "", Master!E3), "") -> 46026 | G3: =IFERROR(IF(Master!F3="", "", Master!F3), "") -> 46027 | H3: =IFERROR(IF(Master!G3="", "", Master!G3), "") -> 46028 | I3: =IFERROR(IF(Master!H3="", "", Master!H3), "") -> 46029 | J3: =IFERROR(IF(Master!I3="", "", Master!I3), "") -> 46030 | ... AG3: =IFERROR(IF(Master!AF3="", "", Master!AF3), "") -> 46053
C4: =TEXT(C3,"ddd") -> Thu | D4: =TEXT(D3,"ddd") -> Fri | E4: =TEXT(E3,"ddd") -> Sat | F4: =TEXT(F3,"ddd") -> Sun | G4: =TEXT(G3,"ddd") -> Mon | H4: =TEXT(H3,"ddd") -> Tue | I4: =TEXT(I3,"ddd") -> Wed | J4: =TEXT(J3,"ddd") -> Thu | ... AG4: =TEXT(AG3,"ddd") -> Sat
C5: =IFERROR(IF(Master!B5="", "", Master!B5), "") -> A Lam | D5: =IFERROR(IF(Master!C5="", "", Master!C5), "") -> A Lam | E5: =IFERROR(IF(Master!D5="", "", Master!D5), "") -> A Lam | F5: =IFERROR(IF(Master!E5="", "", Master!E5), "") -> A Lam | G5: Dicky | H5: Dicky | I5: Dicky | J5: Dicky | K5: Dicky | L5: Dicky | M5: Dicky | N5: =IFERROR(IF(Master!M5="", "", Master!M5), "") -> Amy | O5: =IFERROR(IF(Master!N5="", "", Master!N5), "") -> Amy | P5: =IFERROR(IF(Master!O5="", "", Master!O5), "") -> Amy | Q5: =IFERROR(IF(Master!P5="", "", Master!P5), "") -> Ka Po | R5: Amy | S5: =IFERROR(IF(Master!R5="", "", Master!R5), "") -> Amy | T5: =IFERROR(IF(Master!S5="", "", Master!S5), "") -> Amy | U5: =IFERROR(IF(Master!T5="", "", Master!T5), "") -> Amy | V5: Amy | W5: =IFERROR(IF(Master!V5="", "", Master!V5), "") -> Amy | X5: =IFERROR(IF(Master!W5="", "", Master!W5), "") -> Amy | Y5: =IFERROR(IF(Master!X5="", "", Master!X5), "") -> Amy | Z5: =IFERROR(IF(Master!Y5="", "", Master!Y5), "") -> Amy | AA5: =IFERROR(IF(Master!Z5="", "", Master!Z5), "") -> Amy | AB5: =IFERROR(IF(Master!AA5="", "", Master!AA5), "") -> Dicky | AC5: =IFERROR(IF(Master!AB5="", "", Master!AB5), "") -> Dicky | AD5: =IFERROR(IF(Master!AC5="", "", Master!AC5), "") -> Dicky | ... AG5: =IFERROR(IF(Master!AF5="", "", Master!AF5), "") -> Dicky
C6: =IFERROR(IF(Master!B6="", "", Master!B6), "") -> Melody | D6: =IFERROR(IF(Master!C6="", "", Master!C6), "") -> Melody | E6: =IFERROR(IF(Master!D6="", "", Master!D6), "") -> Melody | F6: =IFERROR(IF(Master!E6="", "", Master!E6), "") -> Melody | G6: =IFERROR(IF(Master!F6="", "", Master!F6), "") -> Melody | H6: =IFERROR(IF(Master!G6="", "", Master!G6), "") -> Melody | I6: =IFERROR(IF(Master!H6="", "", Master!H6), "") -> Melody | J6: =IFERROR(IF(Master!I6="", "", Master!I6), "") -> Melody | ... AG6: =IFERROR(IF(Master!AF6="", "", Master!AF6), "") -> Ka Po
C7: =IFERROR(IF(Master!B7="", "", Master!B7), "") -> Katrina | D7: =IFERROR(IF(Master!C7="", "", Master!C7), "") -> Katrina | E7: =IFERROR(IF(Master!D7="", "", Master!D7), "") -> Katrina | F7: =IFERROR(IF(Master!E7="", "", Master!E7), "") -> Katrina | G7: =IFERROR(IF(Master!F7="", "", Master!F7), "") -> Ka Po | H7: =IFERROR(IF(Master!G7="", "", Master!G7), "") -> Amy | I7: =IFERROR(IF(Master!H7="", "", Master!H7), "") -> Ka Po | J7: =IFERROR(IF(Master!I7="", "", Master!I7), "") -> Ka Po | ... AG7: =IFERROR(IF(Master!AF7="", "", Master!AF7), "") -> Katrina
C8: =IFERROR(IF(Master!B8="", "", Master!B8), "") | D8: =IFERROR(IF(Master!C8="", "", Master!C8), "") | E8: =IFERROR(IF(Master!D8="", "", Master!D8), "") | F8: =IFERROR(IF(Master!E8="", "", Master!E8), "") | G8: =IFERROR(IF(Master!F8="", "", Master!F8), "") | H8: =IFERROR(IF(Master!G8="", "", Master!G8), "") | I8: =IFERROR(IF(Master!H8="", "", Master!H8), "") | J8: =IFERROR(IF(Master!I8="", "", Master!I8), "") | ... AG8: =IFERROR(IF(Master!AF8="", "", Master!AF8), "")
C9: =IFERROR(IF(Master!B9="", "", Master!B9), "") | D9: =IFERROR(IF(Master!C9="", "", Master!C9), "") | E9: =IFERROR(IF(Master!D9="", "", Master!D9), "") | F9: =IFERROR(IF(Master!E9="", "", Master!E9), "") | G9: =IFERROR(IF(Master!F9="", "", Master!F9), "") | H9: =IFERROR(IF(Master!G9="", "", Master!G9), "") | I9: =IFERROR(IF(Master!H9="", "", Master!H9), "") | J9: =IFERROR(IF(Master!I9="", "", Master!I9), "") | ... AG9: =IFERROR(IF(Master!AF9="", "", Master!AF9), "") -> A LAM
C10: =IFERROR(IF(Master!B10="", "", Master!B10), "") | D10: =IFERROR(IF(Master!C10="", "", Master!C10), "") | E10: =IFERROR(IF(Master!D10="", "", Master!D10), "") | F10: =IFERROR(IF(Master!E10="", "", Master!E10), "") | G10: =IFERROR(IF(Master!F10="", "", Master!F10), "") | H10: =IFERROR(IF(Master!G10="", "", Master!G10), "") | I10: =IFERROR(IF(Master!H10="", "", Master!H10), "") | J10: =IFERROR(IF(Master!I10="", "", Master!I10), "") | ... V10: =IFERROR(IF(Master!U10="", "", Master!U10), "") | W10: Yoko | X10: Yoko | Y10: Yoko | Z10: Yoko | AB10: =IFERROR(IF(Master!AA10="", "", Master!AA10), "") | AC10: =IFERROR(IF(Master!AB10="", "", Master!AB10), "") | AD10: =IFERROR(IF(Master!AC10="", "", Master!AC10), "") | AE10: =IFERROR(IF(Master!AD10="", "", Master!AD10), "") | AF10: =IFERROR(IF(Master!AE10="", "", Master!AE10), "") | AG10: =IFERROR(IF(Master!AF10="", "", Master!AF10), "")
A13: DON’T DELETE THIS ROW | C13: =IF(WEEKDAY(C$16,2)=6, INT((C$16-DATE(2026,1,1))/7)+1, 0) -> 0 | D13: =IF(WEEKDAY(D$16,2)=6, INT((D$16-DATE(2026,1,1))/7)+1, 0) -> 0 | E13: =IF(WEEKDAY(E$16,2)=6, INT((E$16-DATE(2026,1,1))/7)+1, 0) -> 1 | F13: =IF(WEEKDAY(F$16,2)=6, INT((F$16-DATE(2026,1,1))/7)+1, 0) -> 0 | G13: =IF(WEEKDAY(G$16,2)=6, INT((G$16-DATE(2026,1,1))/7)+1, 0) -> 0 | H13: =IF(WEEKDAY(H$16,2)=6, INT((H$16-DATE(2026,1,1))/7)+1, 0) -> 0 | I13: =IF(WEEKDAY(I$16,2)=6, INT((I$16-DATE(2026,1,1))/7)+1, 0) -> 0 | J13: =IF(WEEKDAY(J$16,2)=6, INT((J$16-DATE(2026,1,1))/7)+1, 0) -> 0 | ... AG13: =IF(WEEKDAY(AG$16,2)=6, INT((AG$16-DATE(2026,1,1))/7)+1, 0) -> 5
B16: =B1 -> 2026 | C16: =C3 -> 46023 | D16: =D3 -> 46024 | E16: =E3 -> 46025 | F16: =F3 -> 46026 | G16: =G3 -> 46027 | H16: =H3 -> 46028 | I16: =I3 -> 46029 | J16: =J3 -> 46030 | ... AG16: =AG3 -> 46053 | AK16: Name | AL16: Work | AM16: AL | AN16: Total working hours | AO16: Monthly Balance | AP16: Cumulative balance
A17: Post | B17: Name | C17: =TEXT(C16,"ddd") -> Thu | D17: =TEXT(D16,"ddd") -> Fri | E17: =TEXT(E16,"ddd") -> Sat | F17: =TEXT(F16,"ddd") -> Sun | G17: =TEXT(G16,"ddd") -> Mon | H17: =TEXT(H16,"ddd") -> Tue | I17: =TEXT(I16,"ddd") -> Wed | J17: =TEXT(J16,"ddd") -> Thu | ... AG17: =TEXT(AG16,"ddd") -> Sat
A18: GM | B18: Chan, Man Wai | C18: =IF(COUNTIF(PH!$A:$A,C$16)>0,"PH", IF(AND(SUMPRODUCT(($B$9:$AG$10=IFERROR(VLOOKUP($B18,'On call stat'!$S$3:$T$20,2,FALSE),""))*($B$3:$AG$3=C$16))>0,OR(WEEKDAY(C$16,2)=6,),OR($B18="Chan, Man Wai",$B18="Ng Suet Ping, Yoko",$B18="Li Mui Ying",$B18="Lee Ka Po, Kathy",$B18="Huang Huanrao, Yoyo")),"HDAL", IF(OR(WEEKDAY(C$16,2)=7,AND(WEEKDAY(C$16,2)=6,SUMPRODUCT(($B$9:$AG$10=IFERROR(VLOOKUP($B18,'On call stat'!$S$3:$T$20,2,FALSE),""))*($B$3:$AG$3=C$16))>0)),"DO", IF(SUMPRODUCT(($B$9:$AG$10=IFERROR(VLOOKUP($B18,'On call stat'!$S$3:$T$20,2,FALSE),""))*($B$3:$AG$3=C$16))>0,"AL", IF(WEEKDAY(C$16,2)=6, IF($B18="Chan, Man Wai","HD", IF($B18="Ng Suet Ping, Yoko","HD", IF($B18="Li Mui Ying","HD1", IF($B18="Huang Huanrao, Yoyo",IF(MOD(C$13,2)=1,"HD2",IFERROR(IF(SUMPRODUCT(($B$3:$AG$3=C$16)*($B$5:$AG$7=VLOOKUP($B18,'On call stat'!$S$3:$T$10,2,FALSE)))>0,"D","DO"),"DO")), IF($B18="Lee Ka Po, Kathy",IF(MOD(C$13,2)=0,"HD2",IFERROR(IF(SUMPRODUCT(($B$3:$AG$3=C$16)*($B$5:$AG$7=VLOOKUP($B18,'On call stat'!$S$3:$T$10,2,FALSE)))>0,"D","DO"),"DO")), IF($B18="Fan Hoi Wan, Ivy",IF(MOD(C$13,2)=0,"D",IFERROR(IF(SUMPRODUCT(($B$3:$AG$3=C$16)*($B$5:$AG$7=VLOOKUP($B18,'On call stat'!$S$3:$T$10,2,FALSE)))>0,"D","DO"),"DO")), IFERROR(IF(SUMPRODUCT(($B$3:$AG$3=C$16)*($B$5:$AG$7=VLOOKUP($B18,'On call stat'!$S$3:$T$10,2,FALSE)))>0,"D","DO"),"DO"))))))), IF($B18="Huang Huanrao, Yoyo",IF(MOD(C$13,2)=1,"D1","B6"), IF($B18="Lee Ka Po, Kathy",IF(MOD(C$13,2)=0,"D1","B6"), IFERROR(IF(SUMPRODUCT(($B$3:$AG$3=C$16)*($B$5:$AG$7=VLOOKUP($B18,'On call stat'!$S$3:$T$10,2,FALSE)))>0,"E","D"),"D")))))))) -> PH | D18: =IF(COUNTIF(PH!$A:$A,D$16)>0,"PH", IF(AND(SUMPRODUCT(($B$9:$AG$10=IFERROR(VLOOKUP($B18,'On call stat'!$S$3:$T$20,2,FALSE),""))*($B$3:$AG$3=D$16))>0,OR(WEEKDAY(D$16,2)=6,),OR($B18="Chan, Man Wai",$B18="Ng Suet Ping, Yoko",$B18="Li Mui Ying",$B18="Lee Ka Po, Kathy",$B18="Huang Huanrao, Yoyo")),"HDAL", IF(OR(WEEKDAY(D$16,2)=7,AND(WEEKDAY(D$16,2)=6,SUMPRODUCT(($B$9:$AG$10=IFERROR(VLOOKUP($B18,'On call stat'!$S$3:$T$20,2,FALSE),""))*($B$3:$AG$3=D$16))>0)),"DO", IF(SUMPRODUCT(($B$9:$AG$10=IFERROR(VLOOKUP($B18,'On call stat'!$S$3:$T$20,2,FALSE),""))*($B$3:$AG$3=D$16))>0,"AL", IF(WEEKDAY(D$16,2)=6, IF($B18="Chan, Man Wai","HD", IF($B18="Ng Suet Ping, Yoko","HD", IF($B18="Li Mui Ying","HD1", IF($B18="Huang Huanrao, Yoyo",IF(MOD(D$13,2)=1,"HD2",IFERROR(IF(SUMPRODUCT(($B$3:$AG$3=D$16)*($B$5:$AG$7=VLOOKUP($B18,'On call stat'!$S$3:$T$10,2,FALSE)))>0,"D","DO"),"DO")), IF($B18="Lee Ka Po, Kathy",IF(MOD(D$13,2)=0,"HD2",IFERROR(IF(SUMPRODUCT(($B$3:$AG$3=D$16)*($B$5:$AG$7=VLOOKUP($B18,'On call stat'!$S$3:$T$10,2,FALSE)))>0,"D","DO"),"DO")), IF($B18="Fan Hoi Wan, Ivy",IF(MOD(D$13,2)=0,"D",IFERROR(IF(SUMPRODUCT(($B$3:$AG$3=D$16)*($B$5:$AG$7=VLOOKUP($B18,'On call stat'!$S$3:$T$10,2,FALSE)))>0,"D","DO"),"DO")), IFERROR(IF(SUMPRODUCT(($B$3:$AG$3=D$16)*($B$5:$AG$7=VLOOKUP($B18,'On call stat'!$S$3:$T$10,2,FALSE)))>0,"D","DO"),"DO"))))))), IF($B18="Huang Huanrao, Yoyo",IF(MOD(D$13,2)=1,"D1","B6"), IF($B18="Lee Ka Po, Kathy",IF(MOD(D$13,2)=0,"D1","B6"), IFERROR(IF(SUMPRODUCT(($B$3:$AG$3=D$16)*($B$5:$AG$7=VLOOKUP($B18,'On call stat'!$S$3:$T$10,2,FALSE)))>0,"E","D"),"D")))))))) -> D | E18: =IF(COUNTIF(PH!$A:$A,E$16)>0,"PH", IF(AND(SUMPRODUCT(($B$9:$AG$10=IFERROR(VLOOKUP($B18,'On call stat'!$S$3:$T$20,2,FALSE),""))*($B$3:$AG$3=E$16))>0,OR(WEEKDAY(E$16,2)=6,),OR($B18="Chan, Man Wai",$B18="Ng Suet Ping, Yoko",$B18="Li Mui Ying",$B18="Lee Ka Po, Kathy",$B18="Huang Huanrao, Yoyo")),"HDAL", IF(OR(WEEKDAY(E$16,2)=7,AND(WEEKDAY(E$16,2)=6,SUMPRODUCT(($B$9:$AG$10=IFERROR(VLOOKUP($B18,'On call stat'!$S$3:$T$20,2,FALSE),""))*($B$3:$AG$3=E$16))>0)),"DO", IF(SUMPRODUCT(($B$9:$AG$10=IFERROR(VLOOKUP($B18,'On call stat'!$S$3:$T$20,2,FALSE),""))*($B$3:$AG$3=E$16))>0,"AL", IF(WEEKDAY(E$16,2)=6, IF($B18="Chan, Man Wai","HD", IF($B18="Ng Suet Ping, Yoko","HD", IF($B18="Li Mui Ying","HD1", IF($B18="Huang Huanrao, Yoyo",IF(MOD(E$13,2)=1,"HD2",IFERROR(IF(SUMPRODUCT(($B$3:$AG$3=E$16)*($B$5:$AG$7=VLOOKUP($B18,'On call stat'!$S$3:$T$10,2,FALSE)))>0,"D","DO"),"DO")), IF($B18="Lee Ka Po, Kathy",IF(MOD(E$13,2)=0,"HD2",IFERROR(IF(SUMPRODUCT(($B$3:$AG$3=E$16)*($B$5:$AG$7=VLOOKUP($B18,'On call stat'!$S$3:$T$10,2,FALSE)))>0,"D","DO"),"DO")), IF($B18="Fan Hoi Wan, Ivy",IF(MOD(E$13,2)=0,"D",IFERROR(IF(SUMPRODUCT(($B$3:$AG$3=E$16)*($B$5:$AG$7=VLOOKUP($B18,'On call stat'!$S$3:$T$10,2,FALSE)))>0,"D","DO"),"DO")), IFERROR(IF(SUMPRODUCT(($B$3:$AG$3=E$16)*($B$5:$AG$7=VLOOKUP($B18,'On call stat'!$S$3:$T$10,2,FALSE)))>0,"D","DO"),"DO"))))))), IF($B18="Huang Huanrao, Yoyo",IF(MOD(E$13,2)=1,"D1","B6"), IF($B18="Lee Ka Po, Kathy",IF(MOD(E$13,2)=0,"D1","B6"), IFERROR(IF(SUMPRODUCT(($B$3:$AG$3=E$16)*($B$5:$AG$7=VLOOKUP($B18,'On call stat'!$S$3:$T$10,2,FALSE)))>0,"E","D"),"D")))))))) -> HD | F18: =IF(COUNTIF(PH!$A:$A,F$16)>0,"PH", IF(AND(SUMPRODUCT(($B$9:$AG$10=IFERROR(VLOOKUP($B18,'On call stat'!$S$3:$T$20,2,FALSE),""))*($B$3:$AG$3=F$16))>0,OR(WEEKDAY(F$16,2)=6,),OR($B18="Chan, Man Wai",$B18="Ng Suet Ping, Yoko",$B18="Li Mui Ying",$B18="Lee Ka Po, Kathy",$B18="Huang Huanrao, Yoyo")),"HDAL", IF(OR(WEEKDAY(F$16,2)=7,AND(WEEKDAY(F$16,2)=6,SUMPRODUCT(($B$9:$AG$10=IFERROR(VLOOKUP($B18,'On call stat'!$S$3:$T$20,2,FALSE),""))*($B$3:$AG$3=F$16))>0)),"DO", IF(SUMPRODUCT(($B$9:$AG$10=IFERROR(VLOOKUP($B18,'On call stat'!$S$3:$T$20,2,FALSE),""))*($B$3:$AG$3=F$16))>0,"AL", IF(WEEKDAY(F$16,2)=6, IF($B18="Chan, Man Wai","HD", IF($B18="Ng Suet Ping, Yoko","HD", IF($B18="Li Mui Ying","HD1", IF($B18="Huang Huanrao, Yoyo",IF(MOD(F$13,2)=1,"HD2",IFERROR(IF(SUMPRODUCT(($B$3:$AG$3=F$16)*($B$5:$AG$7=VLOOKUP($B18,'On call stat'!$S$3:$T$10,2,FALSE)))>0,"D","DO"),"DO")), IF($B18="Lee Ka Po, Kathy",IF(MOD(F$13,2)=0,"HD2",IFERROR(IF(SUMPRODUCT(($B$3:$AG$3=F$16)*($B$5:$AG$7=VLOOKUP($B18,'On call stat'!$S$3:$T$10,2,FALSE)))>0,"D","DO"),"DO")), IF($B18="Fan Hoi Wan, Ivy",IF(MOD(F$13,2)=0,"D",IFERROR(IF(SUMPRODUCT(($B$3:$AG$3=F$16)*($B$5:$AG$7=VLOOKUP($B18,'On call stat'!$S$3:$T$10,2,FALSE)))>0,"D","DO"),"DO")), IFERROR(IF(SUMPRODUCT(($B$3:$AG$3=F$16)*($B$5:$AG$7=VLOOKUP($B18,'On call stat'!$S$3:$T$10,2,FALSE)))>0,"D","DO"),"DO"))))))), IF($B18="Huang Huanrao, Yoyo",IF(MOD(F$13,2)=1,"D1","B6"), IF($B18="Lee Ka Po, Kathy",IF(MOD(F$13,2)=0,"D1","B6"), IFERROR(IF(SUMPRODUCT(($B$3:$AG$3=F$16)*($B$5:$AG$7=VLOOKUP($B18,'On call stat'!$S$3:$T$10,2,FALSE)))>0,"E","D"),"D")))))))) -> DO | G18: =IF(COUNTIF(PH!$A:$A,G$16)>0,"PH", IF(AND(SUMPRODUCT(($B$9:$AG$10=IFERROR(VLOOKUP($B18,'On call stat'!$S$3:$T$20,2,FALSE),""))*($B$3:$AG$3=G$16))>0,OR(WEEKDAY(G$16,2)=6,),OR($B18="Chan, Man Wai",$B18="Ng Suet Ping, Yoko",$B18="Li Mui Ying",$B18="Lee Ka Po, Kathy",$B18="Huang Huanrao, Yoyo")),"HDAL", IF(OR(WEEKDAY(G$16,2)=7,AND(WEEKDAY(G$16,2)=6,SUMPRODUCT(($B$9:$AG$10=IFERROR(VLOOKUP($B18,'On call stat'!$S$3:$T$20,2,FALSE),""))*($B$3:$AG$3=G$16))>0)),"DO", IF(SUMPRODUCT(($B$9:$AG$10=IFERROR(VLOOKUP($B18,'On call stat'!$S$3:$T$20,2,FALSE),""))*($B$3:$AG$3=G$16))>0,"AL", IF(WEEKDAY(G$16,2)=6, IF($B18="Chan, Man Wai","HD", IF($B18="Ng Suet Ping, Yoko","HD", IF($B18="Li Mui Ying","HD1", IF($B18="Huang Huanrao, Yoyo",IF(MOD(G$13,2)=1,"HD2",IFERROR(IF(SUMPRODUCT(($B$3:$AG$3=G$16)*($B$5:$AG$7=VLOOKUP($B18,'On call stat'!$S$3:$T$10,2,FALSE)))>0,"D","DO"),"DO")), IF($B18="Lee Ka Po, Kathy",IF(MOD(G$13,2)=0,"HD2",IFERROR(IF(SUMPRODUCT(($B$3:$AG$3=G$16)*($B$5:$AG$7=VLOOKUP($B18,'On call stat'!$S$3:$T$10,2,FALSE)))>0,"D","DO"),"DO")), IF($B18="Fan Hoi Wan, Ivy",IF(MOD(G$13,2)=0,"D",IFERROR(IF(SUMPRODUCT(($B$3:$AG$3=G$16)*($B$5:$AG$7=VLOOKUP($B18,'On call stat'!$S$3:$T$10,2,FALSE)))>0,"D","DO"),"DO")), IFERROR(IF(SUMPRODUCT(($B$3:$AG$3=G$16)*($B$5:$AG$7=VLOOKUP($B18,'On call stat'!$S$3:$T$10,2,FALSE)))>0,"D","DO"),"DO"))))))), IF($B18="Huang Huanrao, Yoyo",IF(MOD(G$13,2)=1,"D1","B6"), IF($B18="Lee Ka Po, Kathy",IF(MOD(G$13,2)=0,"D1","B6"), IFERROR(IF(SUMPRODUCT(($B$3:$AG$3=G$16)*($B$5:$AG$7=VLOOKUP($B18,'On call stat'!$S$3:$T$10,2,FALSE)))>0,"E","D"),"D")))))))) -> D | H18: =IF(COUNTIF(PH!$A:$A,H$16)>0,"PH", IF(AND(SUMPRODUCT(($B$9:$AG$10=IFERROR(VLOOKUP($B18,'On call stat'!$S$3:$T$20,2,FALSE),""))*($B$3:$AG$3=H$16))>0,OR(WEEKDAY(H$16,2)=6,),OR($B18="Chan, Man Wai",$B18="Ng Suet Ping, Yoko",$B18="Li Mui Ying",$B18="Lee Ka Po, Kathy",$B18="Huang Huanrao, Yoyo")),"HDAL", IF(OR(WEEKDAY(H$16,2)=7,AND(WEEKDAY(H$16,2)=6,SUMPRODUCT(($B$9:$AG$10=IFERROR(VLOOKUP($B18,'On call stat'!$S$3:$T$20,2,FALSE),""))*($B$3:$AG$3=H$16))>0)),"DO", IF(SUMPRODUCT(($B$9:$AG$10=IFERROR(VLOOKUP($B18,'On call stat'!$S$3:$T$20,2,FALSE),""))*($B$3:$AG$3=H$16))>0,"AL", IF(WEEKDAY(H$16,2)=6, IF($B18="Chan, Man Wai","HD", IF($B18="Ng Suet Ping, Yoko","HD", IF($B18="Li Mui Ying","HD1", IF($B18="Huang Huanrao, Yoyo",IF(MOD(H$13,2)=1,"HD2",IFERROR(IF(SUMPRODUCT(($B$3:$AG$3=H$16)*($B$5:$AG$7=VLOOKUP($B18,'On call stat'!$S$3:$T$10,2,FALSE)))>0,"D","DO"),"DO")), IF($B18="Lee Ka Po, Kathy",IF(MOD(H$13,2)=0,"HD2",IFERROR(IF(SUMPRODUCT(($B$3:$AG$3=H$16)*($B$5:$AG$7=VLOOKUP($B18,'On call stat'!$S$3:$T$10,2,FALSE)))>0,"D","DO"),"DO")), IF($B18="Fan Hoi Wan, Ivy",IF(MOD(H$13,2)=0,"D",IFERROR(IF(SUMPRODUCT(($B$3:$AG$3=H$16)*($B$5:$AG$7=VLOOKUP($B18,'On call stat'!$S$3:$T$10,2,FALSE)))>0,"D","DO"),"DO")), IFERROR(IF(SUMPRODUCT(($B$3:$AG$3=H$16)*($B$5:$AG$7=VLOOKUP($B18,'On call stat'!$S$3:$T$10,2,FALSE)))>0,"D","DO"),"DO"))))))), IF($B18="Huang Huanrao, Yoyo",IF(MOD(H$13,2)=1,"D1","B6"), IF($B18="Lee Ka Po, Kathy",IF(MOD(H$13,2)=0,"D1","B6"), IFERROR(IF(SUMPRODUCT(($B$3:$AG$3=H$16)*($B$5:$AG$7=VLOOKUP($B18,'On call stat'!$S$3:$T$10,2,FALSE)))>0,"E","D"),"D")))))))) -> D | I18: =IF(COUNTIF(PH!$A:$A,I$16)>0,"PH", IF(AND(SUMPRODUCT(($B$9:$AG$10=IFERROR(VLOOKUP($B18,'On call stat'!$S$3:$T$20,2,FALSE),""))*($B$3:$AG$3=I$16))>0,OR(WEEKDAY(I$16,2)=6,),OR($B18="Chan, Man Wai",$B18="Ng Suet Ping, Yoko",$B18="Li Mui Ying",$B18="Lee Ka Po, Kathy",$B18="Huang Huanrao, Yoyo")),"HDAL", IF(OR(WEEKDAY(I$16,2)=7,AND(WEEKDAY(I$16,2)=6,SUMPRODUCT(($B$9:$AG$10=IFERROR(VLOOKUP($B18,'On call stat'!$S$3:$T$20,2,FALSE),""))*($B$3:$AG$3=I$16))>0)),"DO", IF(SUMPRODUCT(($B$9:$AG$10=IFERROR(VLOOKUP($B18,'On call stat'!$S$3:$T$20,2,FALSE),""))*($B$3:$AG$3=I$16))>0,"AL", IF(WEEKDAY(I$16,2)=6, IF($B18="Chan, Man Wai","HD", IF($B18="Ng Suet Ping, Yoko","HD", IF($B18="Li Mui Ying","HD1", IF($B18="Huang Huanrao, Yoyo",IF(MOD(I$13,2)=1,"HD2",IFERROR(IF(SUMPRODUCT(($B$3:$AG$3=I$16)*($B$5:$AG$7=VLOOKUP($B18,'On call stat'!$S$3:$T$10,2,FALSE)))>0,"D","DO"),"DO")), IF($B18="Lee Ka Po, Kathy",IF(MOD(I$13,2)=0,"HD2",IFERROR(IF(SUMPRODUCT(($B$3:$AG$3=I$16)*($B$5:$AG$7=VLOOKUP($B18,'On call stat'!$S$3:$T$10,2,FALSE)))>0,"D","DO"),"DO")), IF($B18="Fan Hoi Wan, Ivy",IF(MOD(I$13,2)=0,"D",IFERROR(IF(SUMPRODUCT(($B$3:$AG$3=I$16)*($B$5:$AG$7=VLOOKUP($B18,'On call stat'!$S$3:$T$10,2,FALSE)))>0,"D","DO"),"DO")), IFERROR(IF(SUMPRODUCT(($B$3:$AG$3=I$16)*($B$5:$AG$7=VLOOKUP($B18,'On call stat'!$S$3:$T$10,2,FALSE)))>0,"D","DO"),"DO"))))))), IF($B18="Huang Huanrao, Yoyo",IF(MOD(I$13,2)=1,"D1","B6"), IF($B18="Lee Ka Po, Kathy",IF(MOD(I$13,2)=0,"D1","B6"), IFERROR(IF(SUMPRODUCT(($B$3:$AG$3=I$16)*($B$5:$AG$7=VLOOKUP($B18,'On call stat'!$S$3:$T$10,2,FALSE)))>0,"E","D"),"D")))))))) -> D | J18: =IF(COUNTIF(PH!$A:$A,J$16)>0,"PH", IF(AND(SUMPRODUCT(($B$9:$AG$10=IFERROR(VLOOKUP($B18,'On call stat'!$S$3:$T$20,2,FALSE),""))*($B$3:$AG$3=J$16))>0,OR(WEEKDAY(J$16,2)=6,),OR($B18="Chan, Man Wai",$B18="Ng Suet Ping, Yoko",$B18="Li Mui Ying",$B18="Lee Ka Po, Kathy",$B18="Huang Huanrao, Yoyo")),"HDAL", IF(OR(WEEKDAY(J$16,2)=7,AND(WEEKDAY(J$16,2)=6,SUMPRODUCT(($B$9:$AG$10=IFERROR(VLOOKUP($B18,'On call stat'!$S$3:$T$20,2,FALSE),""))*($B$3:$AG$3=J$16))>0)),"DO", IF(SUMPRODUCT(($B$9:$AG$10=IFERROR(VLOOKUP($B18,'On call stat'!$S$3:$T$20,2,FALSE),""))*($B$3:$AG$3=J$16))>0,"AL", IF(WEEKDAY(J$16,2)=6, IF($B18="Chan, Man Wai","HD", IF($B18="Ng Suet Ping, Yoko","HD", IF($B18="Li Mui Ying","HD1", IF($B18="Huang Huanrao, Yoyo",IF(MOD(J$13,2)=1,"HD2",IFERROR(IF(SUMPRODUCT(($B$3:$AG$3=J$16)*($B$5:$AG$7=VLOOKUP($B18,'On call stat'!$S$3:$T$10,2,FALSE)))>0,"D","DO"),"DO")), IF($B18="Lee Ka Po, Kathy",IF(MOD(J$13,2)=0,"HD2",IFERROR(IF(SUMPRODUCT(($B$3:$AG$3=J$16)*($B$5:$AG$7=VLOOKUP($B18,'On call stat'!$S$3:$T$10,2,FALSE)))>0,"D","DO"),"DO")), IF($B18="Fan Hoi Wan, Ivy",IF(MOD(J$13,2)=0,"D",IFERROR(IF(SUMPRODUCT(($B$3:$AG$3=J$16)*($B$5:$AG$7=VLOOKUP($B18,'On call stat'!$S$3:$T$10,2,FALSE)))>0,"D","DO"),"DO")), IFERROR(IF(SUMPRODUCT(($B$3:$AG$3=J$16)*($B$5:$AG$7=VLOOKUP($B18,'On call stat'!$S$3:$T$10,2,FALSE)))>0,"D","DO"),"DO"))))))), IF($B18="Huang Huanrao, Yoyo",IF(MOD(J$13,2)=1,"D1","B6"), IF($B18="Lee Ka Po, Kathy",IF(MOD(J$13,2)=0,"D1","B6"), IFERROR(IF(SUMPRODUCT(($B$3:$AG$3=J$16)*($B$5:$AG$7=VLOOKUP($B18,'On call stat'!$S$3:$T$10,2,FALSE)))>0,"E","D"),"D")))))))) -> D | ... AG18: =IF(COUNTIF(PH!$A:$A,AG$16)>0,"PH", IF(AND(SUMPRODUCT(($B$9:$AG$10=IFERROR(VLOOKUP($B18,'On call stat'!$S$3:$T$20,2,FALSE),""))*($B$3:$AG$3=AG$16))>0,OR(WEEKDAY(AG$16,2)=6,),OR($B18="Chan, Man Wai",$B18="Ng Suet Ping, Yoko",$B18="Li Mui Ying",$B18="Lee Ka Po, Kathy",$B18="Huang Huanrao, Yoyo")),"HDAL", IF(OR(WEEKDAY(AG$16,2)=7,AND(WEEKDAY(AG$16,2)=6,SUMPRODUCT(($B$9:$AG$10=IFERROR(VLOOKUP($B18,'On call stat'!$S$3:$T$20,2,FALSE),""))*($B$3:$AG$3=AG$16))>0)),"DO", IF(SUMPRODUCT(($B$9:$AG$10=IFERROR(VLOOKUP($B18,'On call stat'!$S$3:$T$20,2,FALSE),""))*($B$3:$AG$3=AG$16))>0,"AL", IF(WEEKDAY(AG$16,2)=6, IF($B18="Chan, Man Wai","HD", IF($B18="Ng Suet Ping, Yoko","HD", IF($B18="Li Mui Ying","HD1", IF($B18="Huang Huanrao, Yoyo",IF(MOD(AG$13,2)=1,"HD2",IFERROR(IF(SUMPRODUCT(($B$3:$AG$3=AG$16)*($B$5:$AG$7=VLOOKUP($B18,'On call stat'!$S$3:$T$10,2,FALSE)))>0,"D","DO"),"DO")), IF($B18="Lee Ka Po, Kathy",IF(MOD(AG$13,2)=0,"HD2",IFERROR(IF(SUMPRODUCT(($B$3:$AG$3=AG$16)*($B$5:$AG$7=VLOOKUP($B18,'On call stat'!$S$3:$T$10,2,FALSE)))>0,"D","DO"),"DO")), IF($B18="Fan Hoi Wan, Ivy",IF(MOD(AG$13,2)=0,"D",IFERROR(IF(SUMPRODUCT(($B$3:$AG$3=AG$16)*($B$5:$AG$7=VLOOKUP($B18,'On call stat'!$S$3:$T$10,2,FALSE)))>0,"D","DO"),"DO")), IFERROR(IF(SUMPRODUCT(($B$3:$AG$3=AG$16)*($B$5:$AG$7=VLOOKUP($B18,'On call stat'!$S$3:$T$10,2,FALSE)))>0,"D","DO"),"DO"))))))), IF($B18="Huang Huanrao, Yoyo",IF(MOD(AG$13,2)=1,"D1","B6"), IF($B18="Lee Ka Po, Kathy",IF(MOD(AG$13,2)=0,"D1","B6"), IFERROR(IF(SUMPRODUCT(($B$3:$AG$3=AG$16)*($B$5:$AG$7=VLOOKUP($B18,'On call stat'!$S$3:$T$10,2,FALSE)))>0,"E","D"),"D")))))))) -> HD | AK18: Addie | AL18: =SUMPRODUCT((C18:AG18="D")*8) + SUMPRODUCT((C18:AG18="E")*8) + SUMPRODUCT((C18:AG18="HD")*4) -> 188 | AM18: {=SUMPRODUCT((C18:AG18="AL") * (COUNTIF(PH!$A:$A, C$16:AG$16)=0) *(WEEKDAY(C$16:AG$16,2)<=5) * 8)+SUMPRODUCT((C18:AG18="HDAL") * (COUNTIF(PH!$A:$A, C$16:AG$16)=0) *(WEEKDAY(C$16:AG$16,2)<=6) * 4)} -> 0 | AN18: =AL18+AM18 -> 188 | AO18: =AN18-$AN$18 -> 0 | AP18: =AO18 -> 0
A19: SNO | B19: Fan Hoi Wan, Ivy | C19: =IF(COUNTIF(PH!$A:$A,C$16)>0,"PH", IF(AND(SUMPRODUCT(($B$9:$AG$10=IFERROR(VLOOKUP($B19,'On call stat'!$S$3:$T$20,2,FALSE),""))*($B$3:$AG$3=C$16))>0,OR(WEEKDAY(C$16,2)=6,),OR($B19="Chan, Man Wai",$B19="Ng Suet Ping, Yoko",$B19="Li Mui Ying",$B19="Lee Ka Po, Kathy",$B19="Huang Huanrao, Yoyo")),"HDAL", IF(OR(WEEKDAY(C$16,2)=7,AND(WEEKDAY(C$16,2)=6,SUMPRODUCT(($B$9:$AG$10=IFERROR(VLOOKUP($B19,'On call stat'!$S$3:$T$20,2,FALSE),""))*($B$3:$AG$3=C$16))>0)),"DO", IF(SUMPRODUCT(($B$9:$AG$10=IFERROR(VLOOKUP($B19,'On call stat'!$S$3:$T$20,2,FALSE),""))*($B$3:$AG$3=C$16))>0,"AL", IF(WEEKDAY(C$16,2)=6, IF($B19="Chan, Man Wai","HD", IF($B19="Ng Suet Ping, Yoko","HD", IF($B19="Li Mui Ying","HD1", IF($B19="Huang Huanrao, Yoyo",IF(MOD(C$13,2)=1,"HD2",IFERROR(IF(SUMPRODUCT(($B$3:$AG$3=C$16)*($B$5:$AG$7=VLOOKUP($B19,'On call stat'!$S$3:$T$10,2,FALSE)))>0,"D","DO"),"DO")), IF($B19="Lee Ka Po, Kathy",IF(MOD(C$13,2)=0,"HD2",IFERROR(IF(SUMPRODUCT(($B$3:$AG$3=C$16)*($B$5:$AG$7=VLOOKUP($B19,'On call stat'!$S$3:$T$10,2,FALSE)))>0,"D","DO"),"DO")), IF($B19="Fan Hoi Wan, Ivy",IF(MOD(C$13,2)=0,"D",IFERROR(IF(SUMPRODUCT(($B$3:$AG$3=C$16)*($B$5:$AG$7=VLOOKUP($B19,'On call stat'!$S$3:$T$10,2,FALSE)))>0,"D","DO"),"DO")), IFERROR(IF(SUMPRODUCT(($B$3:$AG$3=C$16)*($B$5:$AG$7=VLOOKUP($B19,'On call stat'!$S$3:$T$10,2,FALSE)))>0,"D","DO"),"DO"))))))), IF($B19="Huang Huanrao, Yoyo",IF(MOD(C$13,2)=1,"D1","B6"), IF($B19="Lee Ka Po, Kathy",IF(MOD(C$13,2)=0,"D1","B6"), IFERROR(IF(SUMPRODUCT(($B$3:$AG$3=C$16)*($B$5:$AG$7=VLOOKUP($B19,'On call stat'!$S$3:$T$10,2,FALSE)))>0,"E","D"),"D")))))))) -> PH | D19: =IF(COUNTIF(PH!$A:$A,D$16)>0,"PH", IF(AND(SUMPRODUCT(($B$9:$AG$10=IFERROR(VLOOKUP($B19,'On call stat'!$S$3:$T$20,2,FALSE),""))*($B$3:$AG$3=D$16))>0,OR(WEEKDAY(D$16,2)=6,),OR($B19="Chan, Man Wai",$B19="Ng Suet Ping, Yoko",$B19="Li Mui Ying",$B19="Lee Ka Po, Kathy",$B19="Huang Huanrao, Yoyo")),"HDAL", IF(OR(WEEKDAY(D$16,2)=7,AND(WEEKDAY(D$16,2)=6,SUMPRODUCT(($B$9:$AG$10=IFERROR(VLOOKUP($B19,'On call stat'!$S$3:$T$20,2,FALSE),""))*($B$3:$AG$3=D$16))>0)),"DO", IF(SUMPRODUCT(($B$9:$AG$10=IFERROR(VLOOKUP($B19,'On call stat'!$S$3:$T$20,2,FALSE),""))*($B$3:$AG$3=D$16))>0,"AL", IF(WEEKDAY(D$16,2)=6, IF($B19="Chan, Man Wai","HD", IF($B19="Ng Suet Ping, Yoko","HD", IF($B19="Li Mui Ying","HD1", IF($B19="Huang Huanrao, Yoyo",IF(MOD(D$13,2)=1,"HD2",IFERROR(IF(SUMPRODUCT(($B$3:$AG$3=D$16)*($B$5:$AG$7=VLOOKUP($B19,'On call stat'!$S$3:$T$10,2,FALSE)))>0,"D","DO"),"DO")), IF($B19="Lee Ka Po, Kathy",IF(MOD(D$13,2)=0,"HD2",IFERROR(IF(SUMPRODUCT(($B$3:$AG$3=D$16)*($B$5:$AG$7=VLOOKUP($B19,'On call stat'!$S$3:$T$10,2,FALSE)))>0,"D","DO"),"DO")), IF($B19="Fan Hoi Wan, Ivy",IF(MOD(D$13,2)=0,"D",IFERROR(IF(SUMPRODUCT(($B$3:$AG$3=D$16)*($B$5:$AG$7=VLOOKUP($B19,'On call stat'!$S$3:$T$10,2,FALSE)))>0,"D","DO"),"DO")), IFERROR(IF(SUMPRODUCT(($B$3:$AG$3=D$16)*($B$5:$AG$7=VLOOKUP($B19,'On call stat'!$S$3:$T$10,2,FALSE)))>0,"D","DO"),"DO"))))))), IF($B19="Huang Huanrao, Yoyo",IF(MOD(D$13,2)=1,"D1","B6"), IF($B19="Lee Ka Po, Kathy",IF(MOD(D$13,2)=0,"D1","B6"), IFERROR(IF(SUMPRODUCT(($B$3:$AG$3=D$16)*($B$5:$AG$7=VLOOKUP($B19,'On call stat'!$S$3:$T$10,2,FALSE)))>0,"E","D"),"D")))))))) -> D | E19: =IF(COUNTIF(PH!$A:$A,E$16)>0,"PH", IF(AND(SUMPRODUCT(($B$9:$AG$10=IFERROR(VLOOKUP($B19,'On call stat'!$S$3:$T$20,2,FALSE),""))*($B$3:$AG$3=E$16))>0,OR(WEEKDAY(E$16,2)=6,),OR($B19="Chan, Man Wai",$B19="Ng Suet Ping, Yoko",$B19="Li Mui Ying",$B19="Lee Ka Po, Kathy",$B19="Huang Huanrao, Yoyo")),"HDAL", IF(OR(WEEKDAY(E$16,2)=7,AND(WEEKDAY(E$16,2)=6,SUMPRODUCT(($B$9:$AG$10=IFERROR(VLOOKUP($B19,'On call stat'!$S$3:$T$20,2,FALSE),""))*($B$3:$AG$3=E$16))>0)),"DO", IF(SUMPRODUCT(($B$9:$AG$10=IFERROR(VLOOKUP($B19,'On call stat'!$S$3:$T$20,2,FALSE),""))*($B$3:$AG$3=E$16))>0,"AL", IF(WEEKDAY(E$16,2)=6, IF($B19="Chan, Man Wai","HD", IF($B19="Ng Suet Ping, Yoko","HD", IF($B19="Li Mui Ying","HD1", IF($B19="Huang Huanrao, Yoyo",IF(MOD(E$13,2)=1,"HD2",IFERROR(IF(SUMPRODUCT(($B$3:$AG$3=E$16)*($B$5:$AG$7=VLOOKUP($B19,'On call stat'!$S$3:$T$10,2,FALSE)))>0,"D","DO"),"DO")), IF($B19="Lee Ka Po, Kathy",IF(MOD(E$13,2)=0,"HD2",IFERROR(IF(SUMPRODUCT(($B$3:$AG$3=E$16)*($B$5:$AG$7=VLOOKUP($B19,'On call stat'!$S$3:$T$10,2,FALSE)))>0,"D","DO"),"DO")), IF($B19="Fan Hoi Wan, Ivy",IF(MOD(E$13,2)=0,"D",IFERROR(IF(SUMPRODUCT(($B$3:$AG$3=E$16)*($B$5:$AG$7=VLOOKUP($B19,'On call stat'!$S$3:$T$10,2,FALSE)))>0,"D","DO"),"DO")), IFERROR(IF(SUMPRODUCT(($B$3:$AG$3=E$16)*($B$5:$AG$7=VLOOKUP($B19,'On call stat'!$S$3:$T$10,2,FALSE)))>0,"D","DO"),"DO"))))))), IF($B19="Huang Huanrao, Yoyo",IF(MOD(E$13,2)=1,"D1","B6"), IF($B19="Lee Ka Po, Kathy",IF(MOD(E$13,2)=0,"D1","B6"), IFERROR(IF(SUMPRODUCT(($B$3:$AG$3=E$16)*($B$5:$AG$7=VLOOKUP($B19,'On call stat'!$S$3:$T$10,2,FALSE)))>0,"E","D"),"D")))))))) -> DO | F19: =IF(COUNTIF(PH!$A:$A,F$16)>0,"PH", IF(AND(SUMPRODUCT(($B$9:$AG$10=IFERROR(VLOOKUP($B19,'On call stat'!$S$3:$T$20,2,FALSE),""))*($B$3:$AG$3=F$16))>0,OR(WEEKDAY(F$16,2)=6,),OR($B19="Chan, Man Wai",$B19="Ng Suet Ping, Yoko",$B19="Li Mui Ying",$B19="Lee Ka Po, Kathy",$B19="Huang Huanrao, Yoyo")),"HDAL", IF(OR(WEEKDAY(F$16,2)=7,AND(WEEKDAY(F$16,2)=6,SUMPRODUCT(($B$9:$AG$10=IFERROR(VLOOKUP($B19,'On call stat'!$S$3:$T$20,2,FALSE),""))*($B$3:$AG$3=F$16))>0)),"DO", IF(SUMPRODUCT(($B$9:$AG$10=IFERROR(VLOOKUP($B19,'On call stat'!$S$3:$T$20,2,FALSE),""))*($B$3:$AG$3=F$16))>0,"AL", IF(WEEKDAY(F$16,2)=6, IF($B19="Chan, Man Wai","HD", IF($B19="Ng Suet Ping, Yoko","HD", IF($B19="Li Mui Ying","HD1", IF($B19="Huang Huanrao, Yoyo",IF(MOD(F$13,2)=1,"HD2",IFERROR(IF(SUMPRODUCT(($B$3:$AG$3=F$16)*($B$5:$AG$7=VLOOKUP($B19,'On call stat'!$S$3:$T$10,2,FALSE)))>0,"D","DO"),"DO")), IF($B19="Lee Ka Po, Kathy",IF(MOD(F$13,2)=0,"HD2",IFERROR(IF(SUMPRODUCT(($B$3:$AG$3=F$16)*($B$5:$AG$7=VLOOKUP($B19,'On call stat'!$S$3:$T$10,2,FALSE)))>0,"D","DO"),"DO")), IF($B19="Fan Hoi Wan, Ivy",IF(MOD(F$13,2)=0,"D",IFERROR(IF(SUMPRODUCT(($B$3:$AG$3=F$16)*($B$5:$AG$7=VLOOKUP($B19,'On call stat'!$S$3:$T$10,2,FALSE)))>0,"D","DO"),"DO")), IFERROR(IF(SUMPRODUCT(($B$3:$AG$3=F$16)*($B$5:$AG$7=VLOOKUP($B19,'On call stat'!$S$3:$T$10,2,FALSE)))>0,"D","DO"),"DO"))))))), IF($B19="Huang Huanrao, Yoyo",IF(MOD(F$13,2)=1,"D1","B6"), IF($B19="Lee Ka Po, Kathy",IF(MOD(F$13,2)=0,"D1","B6"), IFERROR(IF(SUMPRODUCT(($B$3:$AG$3=F$16)*($B$5:$AG$7=VLOOKUP($B19,'On call stat'!$S$3:$T$10,2,FALSE)))>0,"E","D"),"D")))))))) -> DO | G19: =IF(COUNTIF(PH!$A:$A,G$16)>0,"PH", IF(AND(SUMPRODUCT(($B$9:$AG$10=IFERROR(VLOOKUP($B19,'On call stat'!$S$3:$T$20,2,FALSE),""))*($B$3:$AG$3=G$16))>0,OR(WEEKDAY(G$16,2)=6,),OR($B19="Chan, Man Wai",$B19="Ng Suet Ping, Yoko",$B19="Li Mui Ying",$B19="Lee Ka Po, Kathy",$B19="Huang Huanrao, Yoyo")),"HDAL", IF(OR(WEEKDAY(G$16,2)=7,AND(WEEKDAY(G$16,2)=6,SUMPRODUCT(($B$9:$AG$10=IFERROR(VLOOKUP($B19,'On call stat'!$S$3:$T$20,2,FALSE),""))*($B$3:$AG$3=G$16))>0)),"DO", IF(SUMPRODUCT(($B$9:$AG$10=IFERROR(VLOOKUP($B19,'On call stat'!$S$3:$T$20,2,FALSE),""))*($B$3:$AG$3=G$16))>0,"AL", IF(WEEKDAY(G$16,2)=6, IF($B19="Chan, Man Wai","HD", IF($B19="Ng Suet Ping, Yoko","HD", IF($B19="Li Mui Ying","HD1", IF($B19="Huang Huanrao, Yoyo",IF(MOD(G$13,2)=1,"HD2",IFERROR(IF(SUMPRODUCT(($B$3:$AG$3=G$16)*($B$5:$AG$7=VLOOKUP($B19,'On call stat'!$S$3:$T$10,2,FALSE)))>0,"D","DO"),"DO")), IF($B19="Lee Ka Po, Kathy",IF(MOD(G$13,2)=0,"HD2",IFERROR(IF(SUMPRODUCT(($B$3:$AG$3=G$16)*($B$5:$AG$7=VLOOKUP($B19,'On call stat'!$S$3:$T$10,2,FALSE)))>0,"D","DO"),"DO")), IF($B19="Fan Hoi Wan, Ivy",IF(MOD(G$13,2)=0,"D",IFERROR(IF(SUMPRODUCT(($B$3:$AG$3=G$16)*($B$5:$AG$7=VLOOKUP($B19,'On call stat'!$S$3:$T$10,2,FALSE)))>0,"D","DO"),"DO")), IFERROR(IF(SUMPRODUCT(($B$3:$AG$3=G$16)*($B$5:$AG$7=VLOOKUP($B19,'On call stat'!$S$3:$T$10,2,FALSE)))>0,"D","DO"),"DO"))))))), IF($B19="Huang Huanrao, Yoyo",IF(MOD(G$13,2)=1,"D1","B6"), IF($B19="Lee Ka Po, Kathy",IF(MOD(G$13,2)=0,"D1","B6"), IFERROR(IF(SUMPRODUCT(($B$3:$AG$3=G$16)*($B$5:$AG$7=VLOOKUP($B19,'On call stat'!$S$3:$T$10,2,FALSE)))>0,"E","D"),"D")))))))) -> D | H19: =IF(COUNTIF(PH!$A:$A,H$16)>0,"PH", IF(AND(SUMPRODUCT(($B$9:$AG$10=IFERROR(VLOOKUP($B19,'On call stat'!$S$3:$T$20,2,FALSE),""))*($B$3:$AG$3=H$16))>0,OR(WEEKDAY(H$16,2)=6,),OR($B19="Chan, Man Wai",$B19="Ng Suet Ping, Yoko",$B19="Li Mui Ying",$B19="Lee Ka Po, Kathy",$B19="Huang Huanrao, Yoyo")),"HDAL", IF(OR(WEEKDAY(H$16,2)=7,AND(WEEKDAY(H$16,2)=6,SUMPRODUCT(($B$9:$AG$10=IFERROR(VLOOKUP($B19,'On call stat'!$S$3:$T$20,2,FALSE),""))*($B$3:$AG$3=H$16))>0)),"DO", IF(SUMPRODUCT(($B$9:$AG$10=IFERROR(VLOOKUP($B19,'On call stat'!$S$3:$T$20,2,FALSE),""))*($B$3:$AG$3=H$16))>0,"AL", IF(WEEKDAY(H$16,2)=6, IF($B19="Chan, Man Wai","HD", IF($B19="Ng Suet Ping, Yoko","HD", IF($B19="Li Mui Ying","HD1", IF($B19="Huang Huanrao, Yoyo",IF(MOD(H$13,2)=1,"HD2",IFERROR(IF(SUMPRODUCT(($B$3:$AG$3=H$16)*($B$5:$AG$7=VLOOKUP($B19,'On call stat'!$S$3:$T$10,2,FALSE)))>0,"D","DO"),"DO")), IF($B19="Lee Ka Po, Kathy",IF(MOD(H$13,2)=0,"HD2",IFERROR(IF(SUMPRODUCT(($B$3:$AG$3=H$16)*($B$5:$AG$7=VLOOKUP($B19,'On call stat'!$S$3:$T$10,2,FALSE)))>0,"D","DO"),"DO")), IF($B19="Fan Hoi Wan, Ivy",IF(MOD(H$13,2)=0,"D",IFERROR(IF(SUMPRODUCT(($B$3:$AG$3=H$16)*($B$5:$AG$7=VLOOKUP($B19,'On call stat'!$S$3:$T$10,2,FALSE)))>0,"D","DO"),"DO")), IFERROR(IF(SUMPRODUCT(($B$3:$AG$3=H$16)*($B$5:$AG$7=VLOOKUP($B19,'On call stat'!$S$3:$T$10,2,FALSE)))>0,"D","DO"),"DO"))))))), IF($B19="Huang Huanrao, Yoyo",IF(MOD(H$13,2)=1,"D1","B6"), IF($B19="Lee Ka Po, Kathy",IF(MOD(H$13,2)=0,"D1","B6"), IFERROR(IF(SUMPRODUCT(($B$3:$AG$3=H$16)*($B$5:$AG$7=VLOOKUP($B19,'On call stat'!$S$3:$T$10,2,FALSE)))>0,"E","D"),"D")))))))) -> D | I19: =IF(COUNTIF(PH!$A:$A,I$16)>0,"PH", IF(AND(SUMPRODUCT(($B$9:$AG$10=IFERROR(VLOOKUP($B19,'On call stat'!$S$3:$T$20,2,FALSE),""))*($B$3:$AG$3=I$16))>0,OR(WEEKDAY(I$16,2)=6,),OR($B19="Chan, Man Wai",$B19="Ng Suet Ping, Yoko",$B19="Li Mui Ying",$B19="Lee Ka Po, Kathy",$B19="Huang Huanrao, Yoyo")),"HDAL", IF(OR(WEEKDAY(I$16,2)=7,AND(WEEKDAY(I$16,2)=6,SUMPRODUCT(($B$9:$AG$10=IFERROR(VLOOKUP($B19,'On call stat'!$S$3:$T$20,2,FALSE),""))*($B$3:$AG$3=I$16))>0)),"DO", IF(SUMPRODUCT(($B$9:$AG$10=IFERROR(VLOOKUP($B19,'On call stat'!$S$3:$T$20,2,FALSE),""))*($B$3:$AG$3=I$16))>0,"AL", IF(WEEKDAY(I$16,2)=6, IF($B19="Chan, Man Wai","HD", IF($B19="Ng Suet Ping, Yoko","HD", IF($B19="Li Mui Ying","HD1", IF($B19="Huang Huanrao, Yoyo",IF(MOD(I$13,2)=1,"HD2",IFERROR(IF(SUMPRODUCT(($B$3:$AG$3=I$16)*($B$5:$AG$7=VLOOKUP($B19,'On call stat'!$S$3:$T$10,2,FALSE)))>0,"D","DO"),"DO")), IF($B19="Lee Ka Po, Kathy",IF(MOD(I$13,2)=0,"HD2",IFERROR(IF(SUMPRODUCT(($B$3:$AG$3=I$16)*($B$5:$AG$7=VLOOKUP($B19,'On call stat'!$S$3:$T$10,2,FALSE)))>0,"D","DO"),"DO")), IF($B19="Fan Hoi Wan, Ivy",IF(MOD(I$13,2)=0,"D",IFERROR(IF(SUMPRODUCT(($B$3:$AG$3=I$16)*($B$5:$AG$7=VLOOKUP($B19,'On call stat'!$S$3:$T$10,2,FALSE)))>0,"D","DO"),"DO")), IFERROR(IF(SUMPRODUCT(($B$3:$AG$3=I$16)*($B$5:$AG$7=VLOOKUP($B19,'On call stat'!$S$3:$T$10,2,FALSE)))>0,"D","DO"),"DO"))))))), IF($B19="Huang Huanrao, Yoyo",IF(MOD(I$13,2)=1,"D1","B6"), IF($B19="Lee Ka Po, Kathy",IF(MOD(I$13,2)=0,"D1","B6"), IFERROR(IF(SUMPRODUCT(($B$3:$AG$3=I$16)*($B$5:$AG$7=VLOOKUP($B19,'On call stat'!$S$3:$T$10,2,FALSE)))>0,"E","D"),"D")))))))) -> D | J19: =IF(COUNTIF(PH!$A:$A,J$16)>0,"PH", IF(AND(SUMPRODUCT(($B$9:$AG$10=IFERROR(VLOOKUP($B19,'On call stat'!$S$3:$T$20,2,FALSE),""))*($B$3:$AG$3=J$16))>0,OR(WEEKDAY(J$16,2)=6,),OR($B19="Chan, Man Wai",$B19="Ng Suet Ping, Yoko",$B19="Li Mui Ying",$B19="Lee Ka Po, Kathy",$B19="Huang Huanrao, Yoyo")),"HDAL", IF(OR(WEEKDAY(J$16,2)=7,AND(WEEKDAY(J$16,2)=6,SUMPRODUCT(($B$9:$AG$10=IFERROR(VLOOKUP($B19,'On call stat'!$S$3:$T$20,2,FALSE),""))*($B$3:$AG$3=J$16))>0)),"DO", IF(SUMPRODUCT(($B$9:$AG$10=IFERROR(VLOOKUP($B19,'On call stat'!$S$3:$T$20,2,FALSE),""))*($B$3:$AG$3=J$16))>0,"AL", IF(WEEKDAY(J$16,2)=6, IF($B19="Chan, Man Wai","HD", IF($B19="Ng Suet Ping, Yoko","HD", IF($B19="Li Mui Ying","HD1", IF($B19="Huang Huanrao, Yoyo",IF(MOD(J$13,2)=1,"HD2",IFERROR(IF(SUMPRODUCT(($B$3:$AG$3=J$16)*($B$5:$AG$7=VLOOKUP($B19,'On call stat'!$S$3:$T$10,2,FALSE)))>0,"D","DO"),"DO")), IF($B19="Lee Ka Po, Kathy",IF(MOD(J$13,2)=0,"HD2",IFERROR(IF(SUMPRODUCT(($B$3:$AG$3=J$16)*($B$5:$AG$7=VLOOKUP($B19,'On call stat'!$S$3:$T$10,2,FALSE)))>0,"D","DO"),"DO")), IF($B19="Fan Hoi Wan, Ivy",IF(MOD(J$13,2)=0,"D",IFERROR(IF(SUMPRODUCT(($B$3:$AG$3=J$16)*($B$5:$AG$7=VLOOKUP($B19,'On call stat'!$S$3:$T$10,2,FALSE)))>0,"D","DO"),"DO")), IFERROR(IF(SUMPRODUCT(($B$3:$AG$3=J$16)*($B$5:$AG$7=VLOOKUP($B19,'On call stat'!$S$3:$T$10,2,FALSE)))>0,"D","DO"),"DO"))))))), IF($B19="Huang Huanrao, Yoyo",IF(MOD(J$13,2)=1,"D1","B6"), IF($B19="Lee Ka Po, Kathy",IF(MOD(J$13,2)=0,"D1","B6"), IFERROR(IF(SUMPRODUCT(($B$3:$AG$3=J$16)*($B$5:$AG$7=VLOOKUP($B19,'On call stat'!$S$3:$T$10,2,FALSE)))>0,"E","D"),"D")))))))) -> D | ... AG19: =IF(COUNTIF(PH!$A:$A,AG$16)>0,"PH", IF(AND(SUMPRODUCT(($B$9:$AG$10=IFERROR(VLOOKUP($B19,'On call stat'!$S$3:$T$20,2,FALSE),""))*($B$3:$AG$3=AG$16))>0,OR(WEEKDAY(AG$16,2)=6,),OR($B19="Chan, Man Wai",$B19="Ng Suet Ping, Yoko",$B19="Li Mui Ying",$B19="Lee Ka Po, Kathy",$B19="Huang Huanrao, Yoyo")),"HDAL", IF(OR(WEEKDAY(AG$16,2)=7,AND(WEEKDAY(AG$16,2)=6,SUMPRODUCT(($B$9:$AG$10=IFERROR(VLOOKUP($B19,'On call stat'!$S$3:$T$20,2,FALSE),""))*($B$3:$AG$3=AG$16))>0)),"DO", IF(SUMPRODUCT(($B$9:$AG$10=IFERROR(VLOOKUP($B19,'On call stat'!$S$3:$T$20,2,FALSE),""))*($B$3:$AG$3=AG$16))>0,"AL", IF(WEEKDAY(AG$16,2)=6, IF($B19="Chan, Man Wai","HD", IF($B19="Ng Suet Ping, Yoko","HD", IF($B19="Li Mui Ying","HD1", IF($B19="Huang Huanrao, Yoyo",IF(MOD(AG$13,2)=1,"HD2",IFERROR(IF(SUMPRODUCT(($B$3:$AG$3=AG$16)*($B$5:$AG$7=VLOOKUP($B19,'On call stat'!$S$3:$T$10,2,FALSE)))>0,"D","DO"),"DO")), IF($B19="Lee Ka Po, Kathy",IF(MOD(AG$13,2)=0,"HD2",IFERROR(IF(SUMPRODUCT(($B$3:$AG$3=AG$16)*($B$5:$AG$7=VLOOKUP($B19,'On call stat'!$S$3:$T$10,2,FALSE)))>0,"D","DO"),"DO")), IF($B19="Fan Hoi Wan, Ivy",IF(MOD(AG$13,2)=0,"D",IFERROR(IF(SUMPRODUCT(($B$3:$AG$3=AG$16)*($B$5:$AG$7=VLOOKUP($B19,'On call stat'!$S$3:$T$10,2,FALSE)))>0,"D","DO"),"DO")), IFERROR(IF(SUMPRODUCT(($B$3:$AG$3=AG$16)*($B$5:$AG$7=VLOOKUP($B19,'On call stat'!$S$3:$T$10,2,FALSE)))>0,"D","DO"),"DO"))))))), IF($B19="Huang Huanrao, Yoyo",IF(MOD(AG$13,2)=1,"D1","B6"), IF($B19="Lee Ka Po, Kathy",IF(MOD(AG$13,2)=0,"D1","B6"), IFERROR(IF(SUMPRODUCT(($B$3:$AG$3=AG$16)*($B$5:$AG$7=VLOOKUP($B19,'On call stat'!$S$3:$T$10,2,FALSE)))>0,"E","D"),"D")))))))) -> DO | AK19: Ivy | AL19: =SUMPRODUCT((C19:AG19="D")*8) + SUMPRODUCT((C19:AG19="E")*8) + SUMPRODUCT((C19:AG19="HD")*4) -> 184 | AM19: {=SUMPRODUCT((C19:AG19="AL") * (COUNTIF(PH!$A:$A, C$16:AG$16)=0) *(WEEKDAY(C$16:AG$16,2)<=5) * 8)+SUMPRODUCT((C19:AG19="HDAL") * (COUNTIF(PH!$A:$A, C$16:AG$16)=0) *(WEEKDAY(C$16:AG$16,2)<=6) * 4)} -> 0 | AN19: =AL19+AM19 -> 184 | AO19: =AN19-$AN$18 -> -4 | AP19: =AO19 -> -4
